Workbook

Sheet Header
A1: Date | B1: Dive | C1: Transect | D1: Dive_trans | E1: HP_line | F1: Direction | G1: Type | H1: Event_ID | I1: Completed | J1: Current_Dir | K1: Current_Vel | L1: TDR | M1: Comments
A2: 41141 | B2: 6700 | C2: 1 | D2: 67001 | G2: pinnacles | H2: 19fa_pinna | I2: yes | L2: 8
A3: 41139 | B3: 6738 | C3: 2 | D3: =CONCATENATE(B3,C3) -> 67382 | E3: 4 | F3: 169 | G3: original | H3: =CONCATENATE(E3,"_",F3,"_",(LEFT(G3,1))) -> 4_169_o | I3: yes | L3: 8
A4: 41139 | B4: 6738 | C4: 1 | D4: =CONCATENATE(B4,C4) -> 67381 | E4: 3 | F4: 222 | G4: original | H4: =CONCATENATE(E4,"_",F4,"_",(LEFT(G4,1))) -> 3_222_o | I4: yes | L4: 8
A5: 41139 | B5: 6736 | C5: 1 | D5: =CONCATENATE(B5,C5) -> 67361 | E5: 1 | F5: 208 | G5: original | H5: =CONCATENATE(E5,"_",F5,"_",(LEFT(G5,1))) -> 1_208_o | I5: yes | L5: 8
A6: 41139 | B6: 6736 | C6: 2 | D6: =CONCATENATE(B6,C6) -> 67362 | E6: 2 | F6: 190 | G6: original | H6: =CONCATENATE(E6,"_",F6,"_",(LEFT(G6,1))) -> 2_190_o | I6: yes | L6: 8
A7: 41140 | B7: 6739 | C7: 1 | D7: =CONCATENATE(B7,C7) -> 67391 | E7: 6 | F7: 136 | G7: original | H7: =CONCATENATE(E7,"_",F7,"_",(LEFT(G7,1))) -> 6_136_o | I7: yes | L7: 8
A8: 41140 | B8: 6739 | C8: 2 | D8: =CONCATENATE(B8,C8) -> 67392 | E8: 5 | F8: 135 | G8: original | H8: =CONCATENATE(E8,"_",F8,"_",(LEFT(G8,1))) -> 5_135_o | I8: yes | L8: 8
A9: 41140 | B9: 6740 | C9: 1 | D9: =CONCATENATE(B9,C9) -> 67401 | E9: 7 | F9: 95 | G9: original | H9: =CONCATENATE(E9,"_",F9,"_",(LEFT(G9,1))) -> 7_95_o | I9: yes | L9: 8
A10: 41140 | B10: 6741 | C10: 2 | D10: =CONCATENATE(B10,C10) -> 67412 | E10: 9 | F10: 99 | G10: original | H10: =CONCATENATE(E10,"_",F10,"_",(LEFT(G10,1))) -> 9_99_o | I10: yes | L10: 8
A11: 41140 | B11: 6741 | C11: 1 | D11: =CONCATENATE(B11,C11) -> 67411 | E11: 8 | F11: 97 | G11: original | H11: =CONCATENATE(E11,"_",F11,"_",(LEFT(G11,1))) -> 8_97_o | I11: yes | L11: 8
A12: 41140 | B12: 6742 | C12: 2 | D12: =CONCATENATE(B12,C12) -> 67422 | E12: 11 | F12: 196 | G12: original | H12: =CONCATENATE(E12,"_",F12,"_",(LEFT(G12,1))) -> 11_196_o | I12: yes | L12: 8
A13: 41140 | B13: 6742 | C13: 1 | D13: =CONCATENATE(B13,C13) -> 67421 | E13: 10 | F13: 186 | G13: original | H13: =CONCATENATE(E13,"_",F13,"_",(LEFT(G13,1))) -> 10_186_o | I13: yes | L13: 8
A14: 41140 | B14: 6746 | C14: 2 | D14: =CONCATENATE(B14,C14) -> 67462 | E14: 17 | F14: 134 | G14: original | H14: =CONCATENATE(E14,"_",F14,"_",(LEFT(G14,1))) -> 17_134_o | I14: yes | L14: 8
... A23: 41141 | B23: 6748 | C23: 3 | D23: =CONCATENATE(B23,C23) -> 67483 | E23: 20 | F23: 149 | G23: original | H23: =CONCATENATE(E23,"_",F23,"_",(LEFT(G23,1))) -> 20_149_o | I23: yes | L23: 8
A24: 41142 | B24: 6755 | C24: 2 | D24: =CONCATENATE(B24,C24) -> 67552 | E24: 28 | F24: 265 | G24: original | H24: =CONCATENATE(E24,"_",F24,"_",(LEFT(G24,1))) -> 28_265_o | I24: yes | L24: 8 | M24: Caught by longline gear, resurfaced, restart on same line
A25: 41142 | B25: 6755 | C25: 1 | D25: =CONCATENATE(B25,C25) -> 67551 | E25: 27 | F25: 260 | G25: original | H25: =CONCATENATE(E25,"_",F25,"_",(LEFT(G25,1))) -> 27_260_o | I25: yes | L25: 8
A26: 41142 | B26: 6754 | C26: 1 | D26: =CONCATENATE(B26,C26) -> 67541 | E26: 26 | F26: 260 | G26: original | H26: =CONCATENATE(E26,"_",F26,"_",(LEFT(G26,1))) -> 26_260_o | I26: yes | L26: 8
A27: 41142 | B27: 6749 | C27: 1 | D27: =CONCATENATE(B27,C27) -> 67491 | E27: 22 | F27: 261 | G27: original | H27: =CONCATENATE(E27,"_",F27,"_",(LEFT(G27,1))) -> 22_261_o | I27: yes | L27: 8
A28: 41142 | B28: 6749 | C28: 2 | D28: =CONCATENATE(B28,C28) -> 67492 | E28: 23 | F28: 202 | G28: original | H28: =CONCATENATE(E28,"_",F28,"_",(LEFT(G28,1))) -> 23_202_o | I28: yes | L28: 8
A29: 41142 | B29: 6753 | C29: 2 | D29: =CONCATENATE(B29,C29) -> 67532 | E29: 25 | F29: 225 | G29: original | H29: =CONCATENATE(E29,"_",F29,"_",(LEFT(G29,1))) -> 25_225_o | I29: yes | L29: 8
A30: 41142 | B30: 6753 | C30: 1 | D30: =CONCATENATE(B30,C30) -> 67531 | E30: 24 | F30: 231 | G30: original | H30: =CONCATENATE(E30,"_",F30,"_",(LEFT(G30,1))) -> 24_231_o | I30: yes | L30: 8
A31: 41143 | B31: 6756 | C31: 2 | D31: =CONCATENATE(B31,C31) -> 67562 | E31: 30 | F31: 104 | G31: original | H31: =CONCATENATE(E31,"_",F31,"_",(LEFT(G31,1))) -> 30_104_o | I31: yes | L31: 8
A32: 41143 | B32: 6756 | C32: 1 | D32: =CONCATENATE(B32,C32) -> 67561 | E32: 29 | F32: 267 | G32: original | H32: =CONCATENATE(E32,"_",F32,"_",(LEFT(G32,1))) -> 29_267_o | I32: yes | L32: 8
A33: 41143 | B33: 6757 | C33: 2 | D33: =CONCATENATE(B33,C33) -> 67572 | E33: 32 | F33: 236 | G33: original | H33: =CONCATENATE(E33,"_",F33,"_",(LEFT(G33,1))) -> 32_236_o | I33: yes | L33: 8
A34: 41143 | B34: 6757 | C34: 1 | D34: =CONCATENATE(B34,C34) -> 67571 | E34: 31 | F34: 237 | G34: original | H34: =CONCATENATE(E34,"_",F34,"_",(LEFT(G34,1))) -> 31_237_o | I34: yes | L34: 8
A35: 41144 | B35: 6758 | C35: 1 | D35: =CONCATENATE(B35,C35) -> 67581 | E35: 33 | F35: 217 | G35: original | H35: =CONCATENATE(E35,"_",F35,"_",(LEFT(G35,1))) -> 33_217_o | I35: yes | L35: 8
A36: 41144 | B36: 6758 | C36: 2 | D36: =CONCATENATE(B36,C36) -> 67582 | E36: 34 | F36: 204 | G36: original | H36: =CONCATENATE(E36,"_",F36,"_",(LEFT(G36,1))) -> 34_204_o | I36: yes | L36: 8
... A38: 41144 | B38: 6759 | C38: 1 | D38: =CONCATENATE(B38,C38) -> 67591 | E38: 35 | F38: 229 | G38: original | H38: =CONCATENATE(E38,"_",F38,"_",(LEFT(G38,1))) -> 35_229_o | I38: yes | L38: 8
A39: 41146 | B39: 6760 | C39: 2 | D39: =CONCATENATE(B39,C39) -> 67602 | E39: 38 | F39: 203 | G39: original | H39: =CONCATENATE(E39,"_",F39,"_",(LEFT(G39,1))) -> 38_203_o | I39: no | L39: 8 | M39: Aborted, lights failure.
A40: 41147 | B40: 6762 | C40: 1 | D40: =CONCATENATE(B40,C40) -> 67621 | E40: 41 | F40: 187 | G40: original | H40: =CONCATENATE(E40,"_",F40,"_",(LEFT(G40,1))) -> 41_187_o | I40: yes | L40: 8
A41: 41147 | B41: 6762 | C41: 2 | D41: =CONCATENATE(B41,C41) -> 67622 | E41: 42 | F41: 240 | G41: original | H41: =CONCATENATE(E41,"_",F41,"_",(LEFT(G41,1))) -> 42_240_o | I41: yes | L41: 8
A42: 41147 | B42: 6761 | C42: 1 | D42: =CONCATENATE(B42,C42) -> 67611 | E42: 39 | F42: 173 | G42: original | H42: =CONCATENATE(E42,"_",F42,"_",(LEFT(G42,1))) -> 39_173_o | I42: yes | L42: 8
A43: 41147 | B43: 6761 | C43: 2 | D43: =CONCATENATE(B43,C43) -> 67612 | E43: 40 | F43: 159 | G43: original | H43: =CONCATENATE(E43,"_",F43,"_",(LEFT(G43,1))) -> 40_159_o | I43: yes | L43: 8
A44: 41147 | B44: 6765 | C44: 2 | D44: =CONCATENATE(B44,C44) -> 67652 | E44: 48 | F44: 164 | G44: original | H44: =CONCATENATE(E44,"_",F44,"_",(LEFT(G44,1))) -> 48_164_o | I44: yes | L44: 8
A45: 41147 | B45: 6765 | C45: 1 | D45: =CONCATENATE(B45,C45) -> 67651 | E45: 47 | F45: 140 | G45: original | H45: =CONCATENATE(E45,"_",F45,"_",(LEFT(G45,1))) -> 47_140_o | I45: yes | L45: 8
A46: 41147 | B46: 6773 | C46: 1 | D46: =CONCATENATE(B46,C46) -> 67731 | E46: 58 | F46: 182 | G46: original | H46: =CONCATENATE(E46,"_",F46,"_",(LEFT(G46,1))) -> 58_182_o | I46: yes | L46: 8
A47: 41148 | B47: 6773 | C47: 2 | D47: =CONCATENATE(B47,C47) -> 67732 | E47: 59 | F47: 190 | G47: original | H47: =CONCATENATE(E47,"_",F47,"_",(LEFT(G47,1))) -> 59_190_o | I47: yes | L47: 8
A48: 41148 | B48: 6770 | C48: 1 | D48: =CONCATENATE(B48,C48) -> 67701 | E48: 53 | F48: 215 | G48: original | H48: =CONCATENATE(E48,"_",F48,"_",(LEFT(G48,1))) -> 53_215_o | I48: yes | L48: 8
A49: 41148 | B49: 6770 | C49: 2 | D49: =CONCATENATE(B49,C49) -> 67702 | E49: 54 | F49: 239 | G49: original | H49: =CONCATENATE(E49,"_",F49,"_",(LEFT(G49,1))) -> 54_239_o | I49: yes | L49: 8

Sheet Data_Collection
A1: Dive_Id | B1: TC | C1: Start_End | D1: Comments | E1: YE cnt
A2: 6738-2 | B2: 22:54:10:18 | C2: Start | E2: 5
B3: 23:27:10:26 | C3: End
A4: 6738_1 | B4: 00:02:15:05 | C4: Start | E4: 4
B5: 00:34:38:24 | C5: End
A6: 6736_1 | B6: 01:10:57:09 | C6: Start | E6: 2
B7: 01:40:24:19 | C7: End
A8: 6736_2 | B8: 01:49:53:28 | C8: Start
B9: 02:13:19:22 | C9: End
A10: 6739_1 | B10: 16:49:22:19 | C10: Start | E10: 1
B11: 17:27:51:17 | C11: End
A12: 6739-2 | B12: 17:35:46:19 | C12: Start | E12: 2
B13: 17:38:03:01 | C13: pause
B14: 17:39:20:13 | C14: restart
B15: 17:41:45:04 | C15: pause
B16: 17:42:20:11 | C16: restart
B17: 17:46:08:21 | C17: pause
B18: 17:48:07:23 | C18: restart
B19: 17:58:13:12 | C19: End
A20: 6740_1 | B20: 19:03:28:24 | C20: Start | E20: 6
B21: 19:32:24:00 | C21: End
A22: 6741_2 | B22: 20:11:07:10 | C22: Start
B23: 20:49:40:14 | C23: End
A24: 6741_1 | B24: 21:09:46:18 | C24: Start | E24: 3
B25: 21:38:31:26 | C25: End
A26: 6742_2 | B26: 23:34:24:10 | C26: Start | D26: Check DOE video for header info - checked, good. | E26: 4
B27: 00:02:39:28 | C27: End
A28: 6742_1 | B28: 00:08:10:02 | C28: Start
B29: 00:34:15:17 | C29: End
A30: 6746_2 | B30: 01:45:00:19 | C30: Start | E30: 3
B31: 02:18:54:26 | C31: End
A32: 6746_1 | B32: 02:25:48:25 | C32: Start | D32: Add DOE video header - added. | E32: 11
B33: 02:55:14:16 | C33: End
D34: Time code for yelloweye count
A35: 6745_2 | B35: 15:18:22:15 | C35: Start
B36: 15:26:37:02 | D36: ye, I recorded as 14920 & juvenile
B37: 15:32:37:03 | D37: ye, I recorded as 25699 juvenile
B38: 15:33:16:18 | D38: ye, I recorded as 26890 & subadult
B39: 15:35:58:08 | D39: ye, more like 15:35:52.07, missed in stereo, Added as frame 31711 jye (spec. 51)
B40: 15:36:08:04 | D40: ye, I recorded as 31982 & subadult
...

Sheet Schedule
C1: Plan | E1: Completed
A2: Date | B2: Day | C2: Transects | D2: Cumulative | E2: Transects | F2: Cumulative | G2: Notes
A3: 41139 | B3: Saturday | C3: 4 | D3: =C3 -> 4 | E3: 4 | F3: =E3 -> 4
A4: 41140 | B4: Sunday | C4: 9 | D4: =D3+C4 -> 13 | E4: 9 | F4: =F3+E4 -> 13
A5: 41141 | B5: Monday | C5: 8 | D5: =D4+C5 -> 21 | E5: 8 | F5: =F4+E5 -> 21
A6: 41142 | B6: Tuesday | C6: 7 | D6: =D5+C6 -> 28 | E6: 7 | F6: =F5+E6 -> 28
A7: 41143 | B7: Wednesday | C7: 4 | D7: =D6+C7 -> 32 | E7: 4 | F7: =F6+E7 -> 32
A8: 41144 | B8: Thursday | C8: 10 | D8: =D7+C8 -> 42 | F8: =F7+E8 -> 32
A9: 41145 | B9: Friday | C9: 0 | D9: =D8+C9 -> 42 | F9: =F8+E9 -> 32
A10: 41146 | B10: Saturday | C10: 10 | D10: =D9+C10 -> 52 | F10: =F9+E10 -> 32
A11: 41147 | B11: Sunday | C11: 8 | D11: =D10+C11 -> 60 | F11: =F10+E11 -> 32
A12: 41148 | B12: Monday
A13: 41149 | B13: Tuesday

Sheet Rquipment
A1: Dive | B1: Transect | C1: Lights_stereo_location | D1: Lights_stereo_level | E1: Lights_lower_location | F1: Lights_lower_level | G1: DOE_angle | H1: DOE laser width | I1: Mer_deploy | J1: Mer_angle | K1: Mer laser width | L1: USBL | M1: Vessel_pitch_roll | N1: GPS | O1: Vessel_headiing | P1: ROV_heading | Q1: ROV_pitch | R1: ROV_roll | S1: ROV_altimeter | U1: TDR
A2: =Header!B3 -> 6738 | B2: =Header!C3 -> 2 | C2: between stereo cameras aimed to intersect center of HAOV with ROV 1m off substrate and center of VAOV | D2: Med | E2: on either side of DOE camera aimed straight ahead and down at -30 degrees | F2: Med | G2: -30 | H2: 100 | I2: Short proboscis | J2: -30 | K2: 270 | L2: Tracklink 1500MA | M2: Kongsburg MRUD | N2: Trimble ag132 | O2: Furuno SC60 | P2: DOE_OSD | Q2: Crossbow CXTA01 | R2: Crossbow CXTA01 | S2: Tritech PA500/6 | U2: Tidbit #8
A3: =Header!B4 -> 6738 | B3: =Header!C4 -> 1 | C3: between stereo cameras aimed to intersect center of HAOV with ROV 1m off substrate and center of VAOV | D3: Med | E3: on either side of DOE camera aimed straight ahead and down at -30 degrees | F3: Med | G3: -30 | H3: 100 | I3: Short proboscis | J3: -30 | K3: 270 | L3: Tracklink 1500MA | M3: Kongsburg MRUD | N3: Trimble ag132 | O3: Furuno SC60 | P3: DOE_OSD | Q3: Crossbow CXTA01 | R3: Crossbow CXTA01 | S3: Tritech PA500/6 | U3: Tidbit #8
A4: =Header!B5 -> 6736 | B4: =Header!C5 -> 1 | C4: between stereo cameras aimed to intersect center of HAOV with ROV 1m off substrate and center of VAOV | D4: Med | E4: on either side of DOE camera aimed straight ahead and down at -30 degrees | F4: Med | G4: -30 | H4: 100 | I4: Short proboscis | J4: -30 | K4: 270 | L4: Tracklink 1500MA | M4: Kongsburg MRUD | N4: Trimble ag132 | O4: Furuno SC60 | P4: DOE_OSD | Q4: Crossbow CXTA01 | R4: Crossbow CXTA01 | S4: Tritech PA500/6 | U4: Tidbit #8
A5: =Header!B6 -> 6736 | B5: =Header!C6 -> 2 | C5: between stereo cameras aimed to intersect center of HAOV with ROV 1m off substrate and center of VAOV | D5: Med | E5: on either side of DOE camera aimed straight ahead and down at -30 degrees | F5: Med | G5: -30 | H5: 100 | I5: Short proboscis | J5: -30 | K5: 270 | L5: Tracklink 1500MA | M5: Kongsburg MRUD | N5: Trimble ag132 | O5: Furuno SC60 | P5: DOE_OSD | Q5: Crossbow CXTA01 | R5: Crossbow CXTA01 | S5: Tritech PA500/6 | U5: Tidbit #8
A6: =Header!B7 -> 6739 | B6: =Header!C7 -> 1 | C6: between stereo cameras aimed to intersect center of HAOV with ROV 1m off substrate and center of VAOV | D6: Med | E6: on either side of DOE camera aimed straight ahead and down at -30 degrees | F6: Low | G6: -30 | H6: 100 | I6: Short proboscis | J6: -30 | K6: 270 | L6: Tracklink 1500MA | M6: Kongsburg MRUD | N6: Trimble ag132 | O6: Furuno SC60 | P6: DOE_OSD | Q6: Crossbow CXTA01 | R6: Crossbow CXTA01 | S6: Tritech PA500/6 | U6: Tidbit #8
A7: =Header!B8 -> 6739 | B7: =Header!C8 -> 2 | C7: between stereo cameras aimed to intersect center of HAOV with ROV 1m off substrate and center of VAOV | D7: Med | E7: on either side of DOE camera aimed straight ahead and down at -30 degrees | F7: Low | G7: -30 | H7: 100 | I7: Short proboscis | J7: -30 | K7: 270 | L7: Tracklink 1500MA | M7: Kongsburg MRUD | N7: Trimble ag132 | O7: Furuno SC60 | P7: DOE_OSD | Q7: Crossbow CXTA01 | R7: Crossbow CXTA01 | S7: Tritech PA500/6 | U7: Tidbit #8
A8: =Header!B9 -> 6740 | B8: =Header!C9 -> 1 | C8: between stereo cameras aimed to intersect center of HAOV with ROV 1m off substrate and center of VAOV | D8: Med | E8: on either side of DOE camera aimed straight ahead and down at -30 degrees | F8: Low | G8: -30 | H8: 100 | I8: Short proboscis | J8: -30 | K8: 270 | L8: Tracklink 1500MA | M8: Kongsburg MRUD | N8: Trimble ag132 | O8: Furuno SC60 | P8: DOE_OSD | Q8: Crossbow CXTA01 | R8: Crossbow CXTA01 | S8: Tritech PA500/6 | U8: Tidbit #8
A9: =Header!B10 -> 6741 | B9: =Header!C10 -> 2 | C9: between stereo cameras aimed to intersect center of HAOV with ROV 1m off substrate and center of VAOV | D9: Med | E9: on either side of DOE camera aimed straight ahead and down at -30 degrees | F9: Low | G9: -30 | H9: 100 | I9: Short proboscis | J9: -30 | K9: 270 | L9: Tracklink 1500MA | M9: Kongsburg MRUD | N9: Trimble ag132 | O9: Furuno SC60 | P9: DOE_OSD | Q9: Crossbow CXTA01 | R9: Crossbow CXTA01 | S9: Tritech PA500/6 | U9: Tidbit #8
A10: =Header!B11 -> 6741 | B10: =Header!C11 -> 1 | C10: between stereo cameras aimed to intersect center of HAOV with ROV 1m off substrate and center of VAOV | D10: Med | E10: on either side of DOE camera aimed straight ahead and down at -30 degrees | F10: Low | G10: -30 | H10: 100 | I10: Short proboscis | J10: -30 | K10: 270 | L10: Tracklink 1500MA | M10: Kongsburg MRUD | N10: Trimble ag132 | O10: Furuno SC60 | P10: DOE_OSD | Q10: Crossbow CXTA01 | R10: Crossbow CXTA01 | S10: Tritech PA500/6 | U10: Tidbit #8
A11: =Header!B12 -> 6742 | B11: =Header!C12 -> 2 | C11: between stereo cameras aimed to intersect center of HAOV with ROV 1m off substrate and center of VAOV | D11: Med | E11: on either side of DOE camera aimed straight ahead and down at -30 degrees | F11: Low | G11: -30 | H11: 100 | I11: Short proboscis | J11: -30 | K11: 270 | L11: Tracklink 1500MA | M11: Kongsburg MRUD | N11: Trimble ag132 | O11: Furuno SC60 | P11: DOE_OSD | Q11: Crossbow CXTA01 | R11: Crossbow CXTA01 | S11: Tritech PA500/6 | U11: Tidbit #8
A12: =Header!B13 -> 6742 | B12: =Header!C13 -> 1 | C12: between stereo cameras aimed to intersect center of HAOV with ROV 1m off substrate and center of VAOV | D12: Med | E12: on either side of DOE camera aimed straight ahead and down at -30 degrees | F12: Low | G12: -30 | H12: 100 | I12: Short proboscis | J12: -30 | K12: 270 | L12: Tracklink 1500MA | M12: Kongsburg MRUD | N12: Trimble ag132 | O12: Furuno SC60 | P12: DOE_OSD | Q12: Crossbow CXTA01 | R12: Crossbow CXTA01 | S12: Tritech PA500/6 | U12: Tidbit #8
A13: =Header!B14 -> 6746 | B13: =Header!C14 -> 2 | C13: between stereo cameras aimed to intersect center of HAOV with ROV 1m off substrate and center of VAOV | D13: Med | E13: on either side of DOE camera aimed straight ahead and down at -30 degrees | F13: Low | G13: -30 | H13: 100 | I13: Short proboscis | J13: -30 | K13: 270 | L13: Tracklink 1500MA | M13: Kongsburg MRUD | N13: Trimble ag132 | O13: Furuno SC60 | P13: DOE_OSD | Q13: Crossbow CXTA01 | R13: Crossbow CXTA01 | S13: Tritech PA500/6 | U13: Tidbit #8
... A48: =Header!B49 -> 6770 | B48: =Header!C49 -> 2 | C48: none | D48: na | E48: on either side and above DOE camera aimed slightly inward and down at -30 degrees | F48: Med | G48: -30 | H48: 100 | I48: Short proboscis | J48: -30 | K48: 270 | L48: Tracklink 1500MA | M48: Kongsburg MRUD | N48: Trimble ag132 | O48: Furuno SC60 | P48: DOE_OSD | Q48: Crossbow CXTA01 | R48: Crossbow CXTA01 | S48: Tritech PA500/6 | U48: Tidbit #8

Sheet Notes
